lfe_motion.tmc
==================

Errors
------
```
Traceback (most recent call last):
  File "/home/travis/miniconda/envs/tc3_linter-env/bin/pytmc", line 6, in <module>
    from pkg_resources import load_entry_point
  File "/home/travis/miniconda/envs/tc3_linter-env/lib/python3.7/site-packages/pkg_resources/__init__.py", line 3251, in <module>
    @_call_aside
  File "/home/travis/miniconda/envs/tc3_linter-env/lib/python3.7/site-packages/pkg_resources/__init__.py", line 3235, in _call_aside
    f(*args, **kwargs)
  File "/home/travis/miniconda/envs/tc3_linter-env/lib/python3.7/site-packages/pkg_resources/__init__.py", line 3264, in _initialize_master_working_set
    working_set = WorkingSet._build_master()
  File "/home/travis/miniconda/envs/tc3_linter-env/lib/python3.7/site-packages/pkg_resources/__init__.py", line 583, in _build_master
    ws.require(__requires__)
  File "/home/travis/miniconda/envs/tc3_linter-env/lib/python3.7/site-packages/pkg_resources/__init__.py", line 900, in require
    needed = self.resolve(parse_requirements(requirements))
  File "/home/travis/miniconda/envs/tc3_linter-env/lib/python3.7/site-packages/pkg_resources/__init__.py", line 786, in resolve
    raise DistributionNotFound(req, requirers)
pkg_resources.DistributionNotFound: The 'epics-pypdb' distribution was not found and is required by pytmc
```

Records
-------
```
```

EPICS database
--------------
```
```
